Workbook

Sheet Podsumowanie
A1: Suma godzin | B1: =SUM(opinie!H:H) -> 1736 | D1: =SUMIF(opinie!W:W, "TRUE", opinie!H:H) -> 1222 | E1: Wody pływowe
A2: Suma godzin na żaglach | B2: =SUM(opinie!I:I) -> 510 | D2: =SUMIF(opinie!W:W, "TRUE", opinie!L:L) -> 5003
A3: Suma godzin na silniku | B3: =SUM(opinie!J:J) -> 906 | D3: =SUMIF(opinie!W:W, "TRUE", opinie!M:M) -> 101
A4: Suma mil | B4: =SUM(opinie!L:L) -> 7143
A5: Ilość dni na morzu | B5: =SUM(opinie!M:M) -> 156
A7: Suma godzin jak JSM | B7: =SUMIF(opinie!Q:Q, "PU/3843", opinie!H:H) -> 1279
A8: Suma godzin jako żeglarz | B8: =SUMIF(opinie!Q:Q, "KT/48", opinie!H:H) -> 457
A10: Suma godzin na Brego | B10: =SUMIF(opinie!P:P, "Brego", opinie!H:H) -> 853
A12: Godziny kapitańskie | B12: =SUMIF(opinie!N:N, "kapitan", opinie!H:H) -> 288
A13: Mile kapitańskie | B13: =SUMIF(opinie!N:N, "kapitan", opinie!L:L) -> 1096 | H13: {=UNIQUE(opinie!O:O)} -> Kapitan
A14: Dni na morzu kapitańskie | B14: =SUMIF(opinie!N:N, "kapitan", opinie!M:M) -> 29 | H14: Antoni Kołodziej | I14: =SUMIF(opinie!O:O, H14, opinie!H:H) -> 46
H15: Krzysztof Jeziorowski | I15: =SUMIF(opinie!O:O, H15, opinie!H:H) -> 448
H16: Paweł Jóźwik | I16: =SUMIF(opinie!O:O, H16, opinie!H:H) -> 45
H17: Jakub Frankiewicz | I17: =SUMIF(opinie!O:O, H17, opinie!H:H) -> 152
H18: Wojciech Sajdak | I18: =SUMIF(opinie!O:O, H18, opinie!H:H) -> 90
A19: Do Kapitana brakuje mi | H19: Jarosław Szeszko | I19: =SUMIF(opinie!O:O, H19, opinie!H:H) -> 54
A20: Godzin na wodach pływowych | B20: 0 | H20: Tomasz Ostrowski | I20: =SUMIF(opinie!O:O, H20, opinie!H:H) -> 97
A21: Na jachcie powyżej 20m | B21: 100 | H21: Marek Załęcki | I21: =SUMIF(opinie!O:O, H21, opinie!H:H) -> 53
A22: Prowadzenia jachtu | B22: =400-B12 -> 112 | H22: Marcin Skalski | I22: =SUMIF(opinie!O:O, H22, opinie!H:H) -> 288
A23: Łacznie godzin | B23: =1200-B7 -> -79 | H23: Bartosz Małecki | I23: =SUMIF(opinie!O:O, H23, opinie!H:H) -> 79
A24: W tym dowolnych godzin | B24: =B23-B22-B21 -> -291 | H24: Mateusz Buta | I24: =SUMIF(opinie!O:O, H24, opinie!H:H) -> 94
H25: Krzyszof Dziechciarz | I25: =SUMIF(opinie!O:O, H25, opinie!H:H) -> 94
H26: Krzysztof Bronikowski | I26: =SUMIF(opinie!O:O, H26, opinie!H:H) -> 102
H27: Andrzej Pochodaj | I27: =SUMIF(opinie!O:O, H27, opinie!H:H) -> 94

Sheet opinie
A1: Nazwa Rejsu | B1: Rok | C1: Zaokrętowanie | D1: Wyokrętowanie | E1: Kraj | F1: Port startowy | G1: Port końcowy | H1: Ilość godzin | I1: Ilość godzin na żaglach | J1: Ilość godzin na silniku | K1: Ilość godzin powyżej 6 B | L1: Ilość mil morskich | M1: Długość rejsu w dniach | N1: Funkcja na jachcie | O1: Kapitan | P1: Nazwa jachtu | Q1: Nr patentu | R1: Kojowe | S1: Składka | T1: Dojazdy | U1: Łaczny koszt | V1: Cena godziny | W1: Wody pływowe | AA1: do poprawy jak dostane opinie
A2: Kana Chorwacja | B2: 2013 | C2: 41531 | D2: 41538 | E2: Chorwacja | F2: Sukosan | G2: Sukosan | H2: =I2+J2 -> 46 | I2: 27 | J2: 19 | K2: 0 | L2: 238 | M2: =D2-C2 -> 7 | N2: załogant | O2: Antoni Kołodziej | P2: Uksa | Q2: KT/48 | U2: =SUM($R2:$T2) -> 0 | W2: FALSE
A3: NNE 2014 | B3: 2014 | E3: Maroko, Hiszpania | F3: Mohamedia | G3: Teneryfa | H3: 120 | K3: 0 | L3: 600 | M3: 7 | N3: załogant | O3: Krzysztof Jeziorowski | Q3: KT/48 | U3: =SUM($R3:$T3) -> 0 | W3: TRUE | AA3: x
A4: WSEX 2017 | B4: 2017 | C4: 42784 | D4: 42791 | E4: Grecja | F4: Alimos Kalamaki | G4: Alimos Kalamaki | H4: =I4+J4 -> 45 | I4: 24 | J4: 21 | K4: 0 | L4: 171 | M4: =D4-C4 -> 7 | N4: załogant | O4: Paweł Jóźwik | Q4: KT/48 | U4: =SUM($R4:$T4) -> 0 | W4: FALSE
A5: Lange 2017 | B5: 2017 | E5: Polska | F5: Szczecin | G5: Szczecin | H5: 40 | K5: 0 | L5: 150 | M5: 4 | N5: załogant | O5: Jakub Frankiewicz | P5: Marengo | Q5: KT/48 | U5: =SUM($R5:$T5) -> 0 | W5: FALSE | AA5: x
A6: NNE 2017 | B6: 2017 | C6: 42945 | D6: 42952 | E6: Szwecja, Finlandia | F6: Ystad | G6: Turku | H6: =I6+J6 -> 112 | I6: 81 | J6: 31 | K6: 0 | L6: 497 | M6: =D6-C6 -> 7 | N6: załogant | O6: Jakub Frankiewicz | P6: Marengo | Q6: KT/48 | U6: =SUM($R6:$T6) -> 0 | W6: FALSE
A7: WSEX 2018 | B7: 2018 | C7: 43148 | D7: 43155 | E7: Hiszpania | F7: Palamos | G7: Palamos | H7: =I7+J7 -> 40 | I7: 20 | J7: 20 | K7: 0 | L7: 170 | M7: =D7-C7 -> 7 | N7: załogant | O7: Wojciech Sajdak | P7: Marina Estrella Four | Q7: KT/48 | U7: =SUM($R7:$T7) -> 0 | W7: FALSE
A8: Kurs sternika morskiego | B8: 2018 | C8: 43246 | D8: 43252 | E8: Polska | F8: Gdynia | G8: Gdynia | H8: =I8+J8 -> 54 | I8: 36 | J8: 18 | K8: 0 | L8: 210 | M8: =D8-C8 -> 6 | N8: kursant | O8: Jarosław Szeszko | P8: - | Q8: KT/48 | U8: =SUM($R8:$T8) -> 0 | W8: FALSE
A9: Chopin 2019 | B9: 2019 | C9: 43596 | D9: 43603 | E9: Holandia, Dania, Szwecja | F9: Amsterdam | G9: Goteborg | H9: =I9+J9 -> 97 | I9: 44 | J9: 53 | K9: 0 | L9: 630 | M9: =D9-C9 -> 7 | N9: załogant | O9: Tomasz Ostrowski | Q9: PU/3843 | U9: =SUM($R9:$T9) -> 0 | W9: TRUE
A10: Lange 2019 | B10: 2019 | C10: 43636 | D10: 43639 | E10: Polska | F10: Szczecin | G10: Szczecin | H10: =I10+J10 -> 53 | I10: 25 | J10: 28 | K10: 0 | L10: 178 | M10: =D10-C10 -> 3 | N10: 3 oficer | O10: Marek Załęcki | P10: Marengo | Q10: PU/3843 | U10: =SUM($R10:$T10) -> 0 | W10: FALSE
A11: SSEX 2019 | B11: 2019 | C11: 43398 | D11: 43406 | E11: Tajlandia | F11: Phuket | G11: Phuket | H11: 50 | K11: 0 | L11: 100 | M11: 7 | N11: załogant | O11: Wojciech Sajdak | Q11: PU/3843 | U11: =SUM($R11:$T11) -> 0 | W11: TRUE | AA11: x
A12: NNE 2019 | B12: 2019 | C12: 43646 | D12: 43659 | E12: Norwegia, Szkocja, Irlandia | F12: Egersund | G12: Dublin | H12: =I12+J12 -> 218 | I12: 27 | J12: 191 | K12: 0 | L12: 656 | M12: =D12-C12 -> 13 | N12: 2 oficer | O12: Krzysztof Jeziorowski | P12: Brego | Q12: PU/3843 | U12: =SUM($R12:$T12) -> 0 | W12: TRUE
A13: Winter 2020 | B13: 2020 | C13: 43877 | D13: 43883 | E13: Czarnogóra | F13: Tivat | G13: Tivat | H13: =I13+J13 -> 30 | I13: 6 | J13: 24 | K13: 0 | L13: 93 | M13: =D13-C13 -> 6 | N13: kapitan | O13: Marcin Skalski | P13: Tango | Q13: PU/3843 | U13: =SUM($R13:$T13) -> 0 | W13: FALSE
A14: NNE 2022 | B14: 2022 | C14: 44780 | D14: 44790 | E14: Norwegia | F14: Tromso | G14: Bodo | H14: =I14+J14 -> 79 | I14: 10.5 | J14: 68.5 | K14: 0 | L14: 295 | M14: =D14-C14 -> 10 | N14: załogant | O14: Bartosz Małecki | P14: Brego | Q14: PU/3843 | U14: =SUM($R14:$T14) -> 0 | W14: TRUE
A15: NNE 2022 | B15: 2022 | C15: 44790 | D15: 44798 | E15: Norwegia | F15: Bodo | G15: Trondheim | H15: =I15+J15 -> 94 | I15: 29 | J15: 65 | K15: 0 | L15: 406 | M15: =D15-C15 -> 8 | N15: 1 oficer | O15: Mateusz Buta | P15: Brego | Q15: PU/3843 | U15: =SUM($R15:$T15) -> 0 | W15: TRUE
A16: NNE 2022 | B16: 2022 | C16: 44798 | D16: 44806 | E16: Norwegia | F16: Trondheim | G16: Bergen | H16: 110 | K16: 0 | L16: 500 | M16: =D16-C16 -> 8 | N16: 4 oficer | O16: Krzysztof Jeziorowski | P16: Brego | Q16: PU/3843 | U16: =SUM($R16:$T16) -> 0 | W16: TRUE | AA16: x
A17: NNE 2023 | B17: 2023 | C17: 45122 | D17: 45129 | E17: Islandia | F17: Rejkjavik | G17: Isafjordur | H17: =I17+J17 -> 78 | I17: 22.5 | J17: 55.5 | K17: 0 | L17: 242 | M17: =D17-C17 -> 7 | N17: kapitan | O17: Marcin Skalski | P17: Brego | Q17: PU/3843 | U17: =SUM($R17:$T17) -> 0 | W17: TRUE
A18: NNE 2023 | B18: 2023 | C18: 45186 | D18: 45194 | E18: Niemcy, Dania | F18: Cuxhavn | G18: Szczecin | H18: =I18+J18 -> 94 | I18: 51.5 | J18: 42.5 | K18: 0 | L18: 433 | M18: =D18-C18 -> 8 | N18: 1 oficer | O18: Krzyszof Dziechciarz | P18: Brego | Q18: PU/3843 | R18: 720 | S18: 500 | T18: 700 | U18: =SUM($R18:$T18) -> 1920 | V18: =U18/H18 -> 20.425532 | W18: FALSE
A19: Nordkap luty | B19: 2024 | C19: 45326 | D19: 45333 | E19: Norwegia | F19: Tromso | G19: Tromso | H19: =I19+J19 -> 102 | I19: 2 | J19: 100 | K19: 0 | L19: 432 | M19: =D19-C19 -> 7 | N19: załogant | O19: Krzysztof Bronikowski | P19: Azimuth | Q19: PU/3843 | R19: 4800 | S19: 1000 | T19: 1000 | U19: =SUM($R19:$T19) -> 6800 | V19: =U19/H19 -> 66.666667 | W19: TRUE
A20: NNE 2024 | B20: 2024 | C20: 45514 | D20: 45521 | E20: Szkocja, Irlandia Północna, Anglia | F20: Troon | G20: Liverpool | H20: =I20+J20 -> 60 | I20: 17 | J20: 43 | K20: 0 | L20: 245 | M20: =D20-C20 -> 7 | N20: kapitan | O20: Marcin Skalski | P20: Brego | Q20: PU/3843 | R20: 0 | S20: 0 | T20: 2000 | U20: =SUM($R20:$T20) -> 2000 | V20: =U20/H20 -> 33.333333 | W20: TRUE
A21: Cape Horn | B21: 2025 | C21: 45759 | D21: 45770 | E21: Argentyna | F21: Ushuaia | G21: Ushuaia | H21: =I21+J21 -> 94 | I21: 16 | J21: 78 | K21: 0 | L21: 381 | M21: =D21-C21 -> 11 | N21: załogant | O21: Andrzej Pochodaj | P21: Selma | Q21: PU/3843 | R21: 15000 | S21: 0 | T21: 6000 | U21: =SUM($R21:$T21) -> 21000 | V21: =U21/H21 -> 223.40426 | W21: TRUE
A22: NNE 2025 | B22: 2025 | C22: 45848 | D22: 45857 | E22: Wyspy Owcze, Islandia | F22: Torshavn | G22: Keflavik | H22: =I22+J22 -> 120 | I22: 71.5 | J22: 48.5 | K22: 0 | L22: 516 | M22: =D22-C22 -> 9 | N22: kapitan | O22: Marcin Skalski | P22: Brego | Q22: PU/3843 | R22: 0 | S22: 0 | T22: 3000 | U22: =SUM($R22:$T22) -> 3000 | V22: =U22/H22 -> 25 | W22: TRUE
H23: =I23+J23 -> 0 | M23: =D23-C23 -> 0 | U23: =SUM($R23:$T23) -> 0 | V23: =U23/H23 -> #DIV/0! | W23: FALSE
H24: =I24+J24 -> 0 | M24: =D24-C24 -> 0 | U24: =SUM($R24:$T24) -> 0 | V24: =U24/H24 -> #DIV/0! | W24: FALSE
H25: =I25+J25 -> 0 | M25: =D25-C25 -> 0 | U25: =SUM($R25:$T25) -> 0 | V25: =U25/H25 -> #DIV/0! | W25: FALSE
H26: =I26+J26 -> 0 | M26: =D26-C26 -> 0 | U26: =SUM($R26:$T26) -> 0 | V26: =U26/H26 -> #DIV/0! | W26: FALSE
H27: =I27+J27 -> 0 | M27: =D27-C27 -> 0 | U27: =SUM($R27:$T27) -> 0 | V27: =U27/H27 -> #DIV/0! | W27: FALSE
H28: =I28+J28 -> 0 | M28: =D28-C28 -> 0 | U28: =SUM($R28:$T28) -> 0 | V28: =U28/H28 -> #DIV/0! | W28: FALSE
H29: =I29+J29 -> 0 | M29: =D29-C29 -> 0 | U29: =SUM($R29:$T29) -> 0 | V29: =U29/H29 -> #DIV/0! | W29: FALSE
H30: =I30+J30 -> 0 | M30: =D30-C30 -> 0 | U30: =SUM($R30:$T30) -> 0 | V30: =U30/H30 -> #DIV/0! | W30: FALSE
H31: =I31+J31 -> 0 | M31: =D31-C31 -> 0 | U31: =SUM($R31:$T31) -> 0 | V31: =U31/H31 -> #DIV/0! | W31: FALSE
H32: =I32+J32 -> 0 | M32: =D32-C32 -> 0 | U32: =SUM($R32:$T32) -> 0 | V32: =U32/H32 -> #DIV/0! | W32: FALSE
H33: =I33+J33 -> 0 | M33: =D33-C33 -> 0 | U33: =SUM($R33:$T33) -> 0 | V33: =U33/H33 -> #DIV/0! | W33: FALSE
H34: =I34+J34 -> 0 | M34: =D34-C34 -> 0 | U34: =SUM($R34:$T34) -> 0 | V34: =U34/H34 -> #DIV/0! | W34: FALSE
... H40: =I40+J40 -> 0 | M40: =D40-C40 -> 0 | U40: =SUM($R40:$T40) -> 0 | V40: =U40/H40 -> #DIV/0! | W40: FALSE
M41: =D41-C41 -> 0 | U41: =SUM($R41:$T41) -> 0 | V41: =U41/H41 -> #DIV/0! | W41: FALSE
M42: =D42-C42 -> 0 | U42: =SUM($R42:$T42) -> 0 | V42: =U42/H42 -> #DIV/0! | W42: FALSE
M43: =D43-C43 -> 0 | U43: =SUM($R43:$T43) -> 0 | V43: =U43/H43 -> #DIV/0! | W43: FALSE
M44: =D44-C44 -> 0 | U44: =SUM($R44:$T44) -> 0 | V44: =U44/H44 -> #DIV/0! | W44: FALSE
M45: =D45-C45 -> 0 | U45: =SUM($R45:$T45) -> 0 | V45: =U45/H45 -> #DIV/0! | W45: FALSE
...

Sheet Analiza
A1: Metric | B1: Value
A2: Total trips | B2: =COUNTA(opinie!A:A)-1 -> 21 | F2: =IFERROR(__xludf.DUMMYFUNCTION("QUERY(opinie!E:E,""select E, count(E) where E is not null group by E"",0)"),"") | G2: =IFERROR(__xludf.DUMMYFUNCTION("""COMPUTED_VALUE"""),"count ") -> count | I2: =IFERROR(__xludf.DUMMYFUNCTION("UNIQUE(ARRAYFORMULA(TRIM(SPLIT(TEXTJOIN("","", TRUE, FILTER(opinie!E:E, (opinie!E:E<>"""")*(ROW(opinie!E:E)>1))), "",""))))"),"Chorwacja") -> Chorwacja | J2: =IFERROR(__xludf.DUMMYFUNCTION("""COMPUTED_VALUE"""),"Maroko") -> Maroko | K2: =IFERROR(__xludf.DUMMYFUNCTION("""COMPUTED_VALUE"""),"Hiszpania") -> Hiszpania | L2: =IFERROR(__xludf.DUMMYFUNCTION("""COMPUTED_VALUE"""),"Grecja") -> Grecja | M2: =IFERROR(__xludf.DUMMYFUNCTION("""COMPUTED_VALUE"""),"Polska") -> Polska | N2: =IFERROR(__xludf.DUMMYFUNCTION("""COMPUTED_VALUE"""),"Szwecja") -> Szwecja | O2: =IFERROR(__xludf.DUMMYFUNCTION("""COMPUTED_VALUE"""),"Finlandia") -> Finlandia | P2: =IFERROR(__xludf.DUMMYFUNCTION("""COMPUTED_VALUE"""),"Hiszpania") -> Hiszpania | Q2: =IFERROR(__xludf.DUMMYFUNCTION("""COMPUTED_VALUE"""),"Polska") -> Polska | R2: =IFERROR(__xludf.DUMMYFUNCTION("""COMPUTED_VALUE"""),"Holandia") -> Holandia | S2: =IFERROR(__xludf.DUMMYFUNCTION("""COMPUTED_VALUE"""),"Dania") -> Dania | T2: =IFERROR(__xludf.DUMMYFUNCTION("""COMPUTED_VALUE"""),"Szwecja") -> Szwecja | U2: =IFERROR(__xludf.DUMMYFUNCTION("""COMPUTED_VALUE"""),"Polska") -> Polska | V2: =IFERROR(__xludf.DUMMYFUNCTION("""COMPUTED_VALUE"""),"Tajlandia") -> Tajlandia | W2: =IFERROR(__xludf.DUMMYFUNCTION("""COMPUTED_VALUE"""),"Norwegia") -> Norwegia | X2: =IFERROR(__xludf.DUMMYFUNCTION("""COMPUTED_VALUE"""),"Szkocja") -> Szkocja | Y2: =IFERROR(__xludf.DUMMYFUNCTION("""COMPUTED_VALUE"""),"Irlandia") -> Irlandia | Z2: =IFERROR(__xludf.DUMMYFUNCTION("""COMPUTED_VALUE"""),"Czarnogóra") -> Czarnogóra | AA2: =IFERROR(__xludf.DUMMYFUNCTION("""COMPUTED_VALUE"""),"Norwegia") -> Norwegia | AB2: =IFERROR(__xludf.DUMMYFUNCTION("""COMPUTED_VALUE"""),"Norwegia") -> Norwegia | AC2: =IFERROR(__xludf.DUMMYFUNCTION("""COMPUTED_VALUE"""),"Norwegia") -> Norwegia | AD2: =IFERROR(__xludf.DUMMYFUNCTION("""COMPUTED_VALUE"""),"Islandia") -> Islandia | AE2: =IFERROR(__xludf.DUMMYFUNCTION("""COMPUTED_VALUE"""),"Niemcy") -> Niemcy | AF2: =IFERROR(__xludf.DUMMYFUNCTION("""COMPUTED_VALUE"""),"Dania") -> Dania | AG2: =IFERROR(__xludf.DUMMYFUNCTION("""COMPUTED_VALUE"""),"Norwegia") -> Norwegia | AH2: =IFERROR(__xludf.DUMMYFUNCTION("""COMPUTED_VALUE"""),"Szkocja") -> Szkocja | AI2: =IFERROR(__xludf.DUMMYFUNCTION("""COMPUTED_VALUE"""),"Irlandia Północna") -> Irlandia Północna | AJ2: =IFERROR(__xludf.DUMMYFUNCTION("""COMPUTED_VALUE"""),"Anglia") -> Anglia | AK2: =IFERROR(__xludf.DUMMYFUNCTION("""COMPUTED_VALUE"""),"Argentyna") -> Argentyna | AL2: =IFERROR(__xludf.DUMMYFUNCTION("""COMPUTED_VALUE"""),"Wyspy Owcze") -> Wyspy Owcze | AM2: =IFERROR(__xludf.DUMMYFUNCTION("""COMPUTED_VALUE"""),"Islandia") -> Islandia
A3: Total miles sailed | B3: =SUM(opinie!L:L) -> 7143 | F3: =IFERROR(__xludf.DUMMYFUNCTION("""COMPUTED_VALUE"""),"Argentyna") -> Argentyna | G3: =IFERROR(__xludf.DUMMYFUNCTION("""COMPUTED_VALUE"""),1.0) -> 1
A4: Total hours | B4: =SUM(opinie!H:H) -> 1736 | F4: =IFERROR(__xludf.DUMMYFUNCTION("""COMPUTED_VALUE"""),"Chorwacja") -> Chorwacja | G4: =IFERROR(__xludf.DUMMYFUNCTION("""COMPUTED_VALUE"""),1.0) -> 1
A5: Total hours sail | B5: =SUM(opinie!I:I) -> 510 | F5: =IFERROR(__xludf.DUMMYFUNCTION("""COMPUTED_VALUE"""),"Czarnogóra") -> Czarnogóra | G5: =IFERROR(__xludf.DUMMYFUNCTION("""COMPUTED_VALUE"""),1.0) -> 1
A6: Total hours engine | B6: =SUM(opinie!J:J) -> 906 | F6: =IFERROR(__xludf.DUMMYFUNCTION("""COMPUTED_VALUE"""),"Grecja") -> Grecja | G6: =IFERROR(__xludf.DUMMYFUNCTION("""COMPUTED_VALUE"""),1.0) -> 1
A7: Miles per sailing hour | B7: =IF(SUM(opinie!I:I)=0,0,SUM(opinie!L:L)/SUM(opinie!I:I)) -> 14.005882 | F7: =IFERROR(__xludf.DUMMYFUNCTION("""COMPUTED_VALUE"""),"Hiszpania") -> Hiszpania | G7: =IFERROR(__xludf.DUMMYFUNCTION("""COMPUTED_VALUE"""),1.0) -> 1
A8: Miles per engine hour | B8: =IF(SUM(opinie!J:J)=0,0,SUM(opinie!L:L)/SUM(opinie!J:J)) -> 7.884106 | F8: =IFERROR(__xludf.DUMMYFUNCTION("""COMPUTED_VALUE"""),"Holandia, Dania, Szwecja") -> Holandia, Dania, Szwecja | G8: =IFERROR(__xludf.DUMMYFUNCTION("""COMPUTED_VALUE"""),1.0) -> 1
A9: % time sailing | B9: =IF(SUM(opinie!H:H)=0,0,SUM(opinie!I:I)/SUM(opinie!H:H)) -> 0.2937788 | F9: =IFERROR(__xludf.DUMMYFUNCTION("""COMPUTED_VALUE"""),"Islandia") -> Islandia | G9: =IFERROR(__xludf.DUMMYFUNCTION("""COMPUTED_VALUE"""),1.0) -> 1
A10: % time engine | B10: =IF(SUM(opinie!H:H)=0,0,SUM(opinie!J:J)/SUM(opinie!H:H)) -> 0.5218894 | F10: =IFERROR(__xludf.DUMMYFUNCTION("""COMPUTED_VALUE"""),"Kraj") -> Kraj | G10: =IFERROR(__xludf.DUMMYFUNCTION("""COMPUTED_VALUE"""),1.0) -> 1
A11: Average trip length | B11: =IFERROR(__xludf.DUMMYFUNCTION("AVERAGE(FILTER(opinie!M:M, opinie!M:M>0))"),7.428571428571429) -> 7.4285714 | F11: =IFERROR(__xludf.DUMMYFUNCTION("""COMPUTED_VALUE"""),"Maroko, Hiszpania") -> Maroko, Hiszpania | G11: =IFERROR(__xludf.DUMMYFUNCTION("""COMPUTED_VALUE"""),1.0) -> 1
A12: Longest trip length | B12: =IFERROR(__xludf.DUMMYFUNCTION("MAX(FILTER(opinie!M:M, opinie!M:M>0))"),13.0) -> 13 | F12: =IFERROR(__xludf.DUMMYFUNCTION("""COMPUTED_VALUE"""),"Niemcy, Dania") -> Niemcy, Dania | G12: =IFERROR(__xludf.DUMMYFUNCTION("""COMPUTED_VALUE"""),1.0) -> 1
A13: Shortest trip length | B13: =IFERROR(__xludf.DUMMYFUNCTION("MIN(FILTER(opinie!M:M, opinie!M:M>0))"),3.0) -> 3 | F13: =IFERROR(__xludf.DUMMYFUNCTION("""COMPUTED_VALUE"""),"Norwegia") -> Norwegia | G13: =IFERROR(__xludf.DUMMYFUNCTION("""COMPUTED_VALUE"""),4.0) -> 4
A14: Total cost | B14: =SUM(opinie!U:U) -> 34720 | F14: =IFERROR(__xludf.DUMMYFUNCTION("""COMPUTED_VALUE"""),"Norwegia, Szkocja, Irlandia") -> Norwegia, Szkocja, Irlandia | G14: =IFERROR(__xludf.DUMMYFUNCTION("""COMPUTED_VALUE"""),1.0) -> 1
A15: Average cost per trip | B15: =IFERROR(__xludf.DUMMYFUNCTION("AVERAGE(FILTER(opinie!U:U, opinie!U:U>0))"),6944.0) -> 6944 | F15: =IFERROR(__xludf.DUMMYFUNCTION("""COMPUTED_VALUE"""),"Polska") -> Polska | G15: =IFERROR(__xludf.DUMMYFUNCTION("""COMPUTED_VALUE"""),3.0) -> 3
A16: Cost per mile | B16: =IF(SUM(opinie!L:L)=0,0,SUM(opinie!U:U)/SUM(opinie!L:L)) -> 4.8607028 | F16: =IFERROR(__xludf.DUMMYFUNCTION("""COMPUTED_VALUE"""),"Szkocja, Irlandia Północna, Anglia") -> Szkocja, Irlandia Północna, Anglia | G16: =IFERROR(__xludf.DUMMYFUNCTION("""COMPUTED_VALUE"""),1.0) -> 1
A17: Cost per day | B17: =IF(SUM(opinie!M:M)=0,0,SUM(opinie!U:U)/SUM(opinie!M:M)) -> 222.5641 | F17: =IFERROR(__xludf.DUMMYFUNCTION("""COMPUTED_VALUE"""),"Szwecja, Finlandia") -> Szwecja, Finlandia | G17: =IFERROR(__xludf.DUMMYFUNCTION("""COMPUTED_VALUE"""),1.0) -> 1
A18: Distinct countries | B18: =IFERROR(__xludf.DUMMYFUNCTION("COUNTA(UNIQUE(TRANSPOSE(SPLIT(TEXTJOIN("", "", TRUE, FILTER(opinie!E2:E1000, opinie!E2:E1000<>"""")), "", ""))))-1"),20.0) -> 20 | F18: =IFERROR(__xludf.DUMMYFUNCTION("""COMPUTED_VALUE"""),"Tajlandia") -> Tajlandia | G18: =IFERROR(__xludf.DUMMYFUNCTION("""COMPUTED_VALUE"""),1.0) -> 1
A19: Most visited country | B19: {=INDEX(F2:F1000, MATCH(MAX(G2:G1000), G2:G1000, 0))} -> Norwegia | F19: =IFERROR(__xludf.DUMMYFUNCTION("""COMPUTED_VALUE"""),"Wyspy Owcze, Islandia") -> Wyspy Owcze, Islandia | G19: =IFERROR(__xludf.DUMMYFUNCTION("""COMPUTED_VALUE"""),1.0) -> 1
A20: Average miles per trip | B20: =IFERROR(__xludf.DUMMYFUNCTION("IF(COUNTA(FILTER(opinie!L:L, opinie!L:L>0))=0,0,SUM(opinie!L:L)/COUNTA(FILTER(opinie!L:L, opinie!L:L>0)))"),324.6818181818182) -> 324.68182
A21: Total days at sea | B21: =SUM(opinie!M:M) -> 156

Sheet Wykresy
A1: =IFERROR(__xludf.DUMMYFUNCTION("QUERY(opinie!B:L, ""select B, sum(L) where B is not null group by B label sum(L) 'Total miles'"", 0)"),"") | B1: =IFERROR(__xludf.DUMMYFUNCTION("""COMPUTED_VALUE"""),"Total miles") -> Total miles
A2: =IFERROR(__xludf.DUMMYFUNCTION("""COMPUTED_VALUE"""),2013.0) -> 2013 | B2: =IFERROR(__xludf.DUMMYFUNCTION("""COMPUTED_VALUE"""),238.0) -> 238
A3: =IFERROR(__xludf.DUMMYFUNCTION("""COMPUTED_VALUE"""),2014.0) -> 2014 | B3: =IFERROR(__xludf.DUMMYFUNCTION("""COMPUTED_VALUE"""),600.0) -> 600
A4: =IFERROR(__xludf.DUMMYFUNCTION("""COMPUTED_VALUE"""),2017.0) -> 2017 | B4: =IFERROR(__xludf.DUMMYFUNCTION("""COMPUTED_VALUE"""),818.0) -> 818
A5: =IFERROR(__xludf.DUMMYFUNCTION("""COMPUTED_VALUE"""),2018.0) -> 2018 | B5: =IFERROR(__xludf.DUMMYFUNCTION("""COMPUTED_VALUE"""),380.0) -> 380
A6: =IFERROR(__xludf.DUMMYFUNCTION("""COMPUTED_VALUE"""),2019.0) -> 2019 | B6: =IFERROR(__xludf.DUMMYFUNCTION("""COMPUTED_VALUE"""),1564.0) -> 1564
A7: =IFERROR(__xludf.DUMMYFUNCTION("""COMPUTED_VALUE"""),2020.0) -> 2020 | B7: =IFERROR(__xludf.DUMMYFUNCTION("""COMPUTED_VALUE"""),93.0) -> 93
A8: =IFERROR(__xludf.DUMMYFUNCTION("""COMPUTED_VALUE"""),2022.0) -> 2022 | B8: =IFERROR(__xludf.DUMMYFUNCTION("""COMPUTED_VALUE"""),1201.0) -> 1201
A9: =IFERROR(__xludf.DUMMYFUNCTION("""COMPUTED_VALUE"""),2023.0) -> 2023 | B9: =IFERROR(__xludf.DUMMYFUNCTION("""COMPUTED_VALUE"""),675.0) -> 675
A10: =IFERROR(__xludf.DUMMYFUNCTION("""COMPUTED_VALUE"""),2024.0) -> 2024 | B10: =IFERROR(__xludf.DUMMYFUNCTION("""COMPUTED_VALUE"""),677.0) -> 677
A11: =IFERROR(__xludf.DUMMYFUNCTION("""COMPUTED_VALUE"""),2025.0) -> 2025 | B11: =IFERROR(__xludf.DUMMYFUNCTION("""COMPUTED_VALUE"""),897.0) -> 897
A14: Hours on Sail | B14: =SUM(opinie!I:I) -> 510
A15: Hours on Engine | B15: =SUM(opinie!J:J) -> 906
A36: =IFERROR(__xludf.DUMMYFUNCTION("QUERY(opinie!B:U, ""select B, sum(U) where B is not null group by B label sum(U) 'Total cost'"", 0)"),"") | B36: =IFERROR(__xludf.DUMMYFUNCTION("""COMPUTED_VALUE"""),"Total cost") -> Total cost
A37: =IFERROR(__xludf.DUMMYFUNCTION("""COMPUTED_VALUE"""),2013.0) -> 2013 | B37: =IFERROR(__xludf.DUMMYFUNCTION("""COMPUTED_VALUE"""),0.0) -> 0 | D37: =IFERROR(__xludf.DUMMYFUNCTION("QUERY(opinie!B:B, ""select B, count(B) where B is not null group by B label count(B) 'Trips count'"", 0)"),"") | E37: =IFERROR(__xludf.DUMMYFUNCTION("""COMPUTED_VALUE"""),"Trips count") -> Trips count
A38: =IFERROR(__xludf.DUMMYFUNCTION("""COMPUTED_VALUE"""),2014.0) -> 2014 | B38: =IFERROR(__xludf.DUMMYFUNCTION("""COMPUTED_VALUE"""),0.0) -> 0 | D38: =IFERROR(__xludf.DUMMYFUNCTION("""COMPUTED_VALUE"""),2013.0) -> 2013 | E38: =IFERROR(__xludf.DUMMYFUNCTION("""COMPUTED_VALUE"""),1.0) -> 1
A39: =IFERROR(__xludf.DUMMYFUNCTION("""COMPUTED_VALUE"""),2017.0) -> 2017 | B39: =IFERROR(__xludf.DUMMYFUNCTION("""COMPUTED_VALUE"""),0.0) -> 0 | D39: =IFERROR(__xludf.DUMMYFUNCTION("""COMPUTED_VALUE"""),2014.0) -> 2014 | E39: =IFERROR(__xludf.DUMMYFUNCTION("""COMPUTED_VALUE"""),1.0) -> 1
A40: =IFERROR(__xludf.DUMMYFUNCTION("""COMPUTED_VALUE"""),2018.0) -> 2018 | B40: =IFERROR(__xludf.DUMMYFUNCTION("""COMPUTED_VALUE"""),0.0) -> 0 | D40: =IFERROR(__xludf.DUMMYFUNCTION("""COMPUTED_VALUE"""),2017.0) -> 2017 | E40: =IFERROR(__xludf.DUMMYFUNCTION("""COMPUTED_VALUE"""),3.0) -> 3
A41: =IFERROR(__xludf.DUMMYFUNCTION("""COMPUTED_VALUE"""),2019.0) -> 2019 | B41: =IFERROR(__xludf.DUMMYFUNCTION("""COMPUTED_VALUE"""),0.0) -> 0 | D41: =IFERROR(__xludf.DUMMYFUNCTION("""COMPUTED_VALUE"""),2018.0) -> 2018 | E41: =IFERROR(__xludf.DUMMYFUNCTION("""COMPUTED_VALUE"""),2.0) -> 2
A42: =IFERROR(__xludf.DUMMYFUNCTION("""COMPUTED_VALUE"""),2020.0) -> 2020 | B42: =IFERROR(__xludf.DUMMYFUNCTION("""COMPUTED_VALUE"""),0.0) -> 0 | D42: =IFERROR(__xludf.DUMMYFUNCTION("""COMPUTED_VALUE"""),2019.0) -> 2019 | E42: =IFERROR(__xludf.DUMMYFUNCTION("""COMPUTED_VALUE"""),4.0) -> 4
A43: =IFERROR(__xludf.DUMMYFUNCTION("""COMPUTED_VALUE"""),2022.0) -> 2022 | B43: =IFERROR(__xludf.DUMMYFUNCTION("""COMPUTED_VALUE"""),0.0) -> 0 | D43: =IFERROR(__xludf.DUMMYFUNCTION("""COMPUTED_VALUE"""),2020.0) -> 2020 | E43: =IFERROR(__xludf.DUMMYFUNCTION("""COMPUTED_VALUE"""),1.0) -> 1
A44: =IFERROR(__xludf.DUMMYFUNCTION("""COMPUTED_VALUE"""),2023.0) -> 2023 | B44: =IFERROR(__xludf.DUMMYFUNCTION("""COMPUTED_VALUE"""),1920.0) -> 1920 | D44: =IFERROR(__xludf.DUMMYFUNCTION("""COMPUTED_VALUE"""),2022.0) -> 2022 | E44: =IFERROR(__xludf.DUMMYFUNCTION("""COMPUTED_VALUE"""),3.0) -> 3
A45: =IFERROR(__xludf.DUMMYFUNCTION("""COMPUTED_VALUE"""),2024.0) -> 2024 | B45: =IFERROR(__xludf.DUMMYFUNCTION("""COMPUTED_VALUE"""),8800.0) -> 8800 | D45: =IFERROR(__xludf.DUMMYFUNCTION("""COMPUTED_VALUE"""),2023.0) -> 2023 | E45: =IFERROR(__xludf.DUMMYFUNCTION("""COMPUTED_VALUE"""),2.0) -> 2
A46: =IFERROR(__xludf.DUMMYFUNCTION("""COMPUTED_VALUE"""),2025.0) -> 2025 | B46: =IFERROR(__xludf.DUMMYFUNCTION("""COMPUTED_VALUE"""),24000.0) -> 24000 | D46: =IFERROR(__xludf.DUMMYFUNCTION("""COMPUTED_VALUE"""),2024.0) -> 2024 | E46: =IFERROR(__xludf.DUMMYFUNCTION("""COMPUTED_VALUE"""),2.0) -> 2
D47: =IFERROR(__xludf.DUMMYFUNCTION("""COMPUTED_VALUE"""),2025.0) -> 2025 | E47: =IFERROR(__xludf.DUMMYFUNCTION("""COMPUTED_VALUE"""),2.0) -> 2

Sheet szkolenia
A1: Data | B1: Nazwa | C1: Organizator | D1: Cena
B2: SRC | C2: - | D2: -
A3: 45676 | B3: Radar RYA | C3: Kliper | D3: 450
A4: 45806 | B4: STCW | C4: Maritime Security | D4: 1550 | E4: https://maritime-security.eu/
A5: 45935 | B5: Kurs z silnika | C5: OceanTeam | D5: 625
